2022-05-14 08:50:29,935 ERROR Internal Server Error: /news/15 /Users/eduardivanov/Yandex.Disk.localized/Documents/python/workspace/pythonProject/venv/lib/python3.8/site-packages/django/utils/log.py (<class 'django.template.exceptions.TemplateDoesNotExist'>, TemplateDoesNotExist('post_1/post.html'), <traceback object at 0x1070f0340>)
Traceback (most recent call last):
  File "/Users/eduardivanov/Yandex.Disk.localized/Documents/python/workspace/pythonProject/venv/lib/python3.8/site-packages/django/core/handlers/exception.py", line 55, in inner
    response = get_response(request)
  File "/Users/eduardivanov/Yandex.Disk.localized/Documents/python/workspace/pythonProject/venv/lib/python3.8/site-packages/django/core/handlers/base.py", line 220, in _get_response
    response = response.render()
  File "/Users/eduardivanov/Yandex.Disk.localized/Documents/python/workspace/pythonProject/venv/lib/python3.8/site-packages/django/template/response.py", line 114, in render
    self.content = self.rendered_content
  File "/Users/eduardivanov/Yandex.Disk.localized/Documents/python/workspace/pythonProject/venv/lib/python3.8/site-packages/django/template/response.py", line 90, in rendered_content
    template = self.resolve_template(self.template_name)
  File "/Users/eduardivanov/Yandex.Disk.localized/Documents/python/workspace/pythonProject/venv/lib/python3.8/site-packages/django/template/response.py", line 72, in resolve_template
    return select_template(template, using=self.using)
  File "/Users/eduardivanov/Yandex.Disk.localized/Documents/python/workspace/pythonProject/venv/lib/python3.8/site-packages/django/template/loader.py", line 47, in select_template
    raise TemplateDoesNotExist(", ".join(template_name_list), chain=chain)
django.template.exceptions.TemplateDoesNotExist: post_1/post.html
2022-05-14 08:50:29,937 ERROR "GET /news/15 HTTP/1.1" 500 81592 /Users/eduardivanov/Yandex.Disk.localized/Documents/python/workspace/pythonProject/venv/lib/python3.8/site-packages/django/core/servers/basehttp.py None
2022-05-14 08:50:37,156 ERROR Internal Server Error: /news/14 /Users/eduardivanov/Yandex.Disk.localized/Documents/python/workspace/pythonProject/venv/lib/python3.8/site-packages/django/utils/log.py (<class 'django.template.exceptions.TemplateDoesNotExist'>, TemplateDoesNotExist('post_1/post.html'), <traceback object at 0x1071202c0>)
Traceback (most recent call last):
  File "/Users/eduardivanov/Yandex.Disk.localized/Documents/python/workspace/pythonProject/venv/lib/python3.8/site-packages/django/core/handlers/exception.py", line 55, in inner
    response = get_response(request)
  File "/Users/eduardivanov/Yandex.Disk.localized/Documents/python/workspace/pythonProject/venv/lib/python3.8/site-packages/django/core/handlers/base.py", line 220, in _get_response
    response = response.render()
  File "/Users/eduardivanov/Yandex.Disk.localized/Documents/python/workspace/pythonProject/venv/lib/python3.8/site-packages/django/template/response.py", line 114, in render
    self.content = self.rendered_content
  File "/Users/eduardivanov/Yandex.Disk.localized/Documents/python/workspace/pythonProject/venv/lib/python3.8/site-packages/django/template/response.py", line 90, in rendered_content
    template = self.resolve_template(self.template_name)
  File "/Users/eduardivanov/Yandex.Disk.localized/Documents/python/workspace/pythonProject/venv/lib/python3.8/site-packages/django/template/response.py", line 72, in resolve_template
    return select_template(template, using=self.using)
  File "/Users/eduardivanov/Yandex.Disk.localized/Documents/python/workspace/pythonProject/venv/lib/python3.8/site-packages/django/template/loader.py", line 47, in select_template
    raise TemplateDoesNotExist(", ".join(template_name_list), chain=chain)
django.template.exceptions.TemplateDoesNotExist: post_1/post.html
2022-05-14 08:50:37,157 ERROR "GET /news/14 HTTP/1.1" 500 81592 /Users/eduardivanov/Yandex.Disk.localized/Documents/python/workspace/pythonProject/venv/lib/python3.8/site-packages/django/core/servers/basehttp.py None
2022-05-14 08:59:21,744 ERROR Internal Server Error: /upgrade/premium/ /Users/eduardivanov/Yandex.Disk.localized/Documents/python/workspace/pythonProject/venv/lib/python3.8/site-packages/django/utils/log.py (<class 'django.contrib.auth.models.Group.DoesNotExist'>, DoesNotExist('Group matching query does not exist.'), <traceback object at 0x103566fc0>)
Traceback (most recent call last):
  File "/Users/eduardivanov/Yandex.Disk.localized/Documents/python/workspace/pythonProject/venv/lib/python3.8/site-packages/django/core/handlers/exception.py", line 55, in inner
    response = get_response(request)
  File "/Users/eduardivanov/Yandex.Disk.localized/Documents/python/workspace/pythonProject/venv/lib/python3.8/site-packages/django/core/handlers/base.py", line 197, in _get_response
    response = wrapped_callback(request, *callback_args, **callback_kwargs)
  File "/Users/eduardivanov/Yandex.Disk.localized/Documents/python/workspace/pythonProject/venv/lib/python3.8/site-packages/django/contrib/auth/decorators.py", line 23, in _wrapped_view
    return view_func(request, *args, **kwargs)
  File "/Users/eduardivanov/Yandex.Disk.localized/Documents/python/workspace/pythonProject/NewsPaper/NewsPaper/views.py", line 46, in upgrade_premium
    premium_group = Group.objects.get(name='premium')
  File "/Users/eduardivanov/Yandex.Disk.localized/Documents/python/workspace/pythonProject/venv/lib/python3.8/site-packages/django/db/models/manager.py", line 85, in manager_method
    return getattr(self.get_queryset(), name)(*args, **kwargs)
  File "/Users/eduardivanov/Yandex.Disk.localized/Documents/python/workspace/pythonProject/venv/lib/python3.8/site-packages/django/db/models/query.py", line 496, in get
    raise self.model.DoesNotExist(
django.contrib.auth.models.Group.DoesNotExist: Group matching query does not exist.
2022-05-14 08:59:21,750 ERROR "GET /upgrade/premium/ HTTP/1.1" 500 80370 /Users/eduardivanov/Yandex.Disk.localized/Documents/python/workspace/pythonProject/venv/lib/python3.8/site-packages/django/core/servers/basehttp.py None
