2022-05-14 08:50:29,935 ERROR Internal Server Error: /news/15 /Users/eduardivanov/Yandex.Disk.localized/Documents/python/workspace/pythonProject/venv/lib/python3.8/site-packages/django/utils/log.py (<class 'django.template.exceptions.TemplateDoesNotExist'>, TemplateDoesNotExist('post_1/post.html'), <traceback object at 0x1070f0340>)
Traceback (most recent call last):
  File "/Users/eduardivanov/Yandex.Disk.localized/Documents/python/workspace/pythonProject/venv/lib/python3.8/site-packages/django/core/handlers/exception.py", line 55, in inner
    response = get_response(request)
  File "/Users/eduardivanov/Yandex.Disk.localized/Documents/python/workspace/pythonProject/venv/lib/python3.8/site-packages/django/core/handlers/base.py", line 220, in _get_response
    response = response.render()
  File "/Users/eduardivanov/Yandex.Disk.localized/Documents/python/workspace/pythonProject/venv/lib/python3.8/site-packages/django/template/response.py", line 114, in render
    self.content = self.rendered_content
  File "/Users/eduardivanov/Yandex.Disk.localized/Documents/python/workspace/pythonProject/venv/lib/python3.8/site-packages/django/template/response.py", line 90, in rendered_content
    template = self.resolve_template(self.template_name)
  File "/Users/eduardivanov/Yandex.Disk.localized/Documents/python/workspace/pythonProject/venv/lib/python3.8/site-packages/django/template/response.py", line 72, in resolve_template
    return select_template(template, using=self.using)
  File "/Users/eduardivanov/Yandex.Disk.localized/Documents/python/workspace/pythonProject/venv/lib/python3.8/site-packages/django/template/loader.py", line 47, in select_template
    raise TemplateDoesNotExist(", ".join(template_name_list), chain=chain)
django.template.exceptions.TemplateDoesNotExist: post_1/post.html
2022-05-14 08:50:29,937 ERROR "GET /news/15 HTTP/1.1" 500 81592 /Users/eduardivanov/Yandex.Disk.localized/Documents/python/workspace/pythonProject/venv/lib/python3.8/site-packages/django/core/servers/basehttp.py None
2022-05-14 08:50:37,156 ERROR Internal Server Error: /news/14 /Users/eduardivanov/Yandex.Disk.localized/Documents/python/workspace/pythonProject/venv/lib/python3.8/site-packages/django/utils/log.py (<class 'django.template.exceptions.TemplateDoesNotExist'>, TemplateDoesNotExist('post_1/post.html'), <traceback object at 0x1071202c0>)
Traceback (most recent call last):
  File "/Users/eduardivanov/Yandex.Disk.localized/Documents/python/workspace/pythonProject/venv/lib/python3.8/site-packages/django/core/handlers/exception.py", line 55, in inner
    response = get_response(request)
  File "/Users/eduardivanov/Yandex.Disk.localized/Documents/python/workspace/pythonProject/venv/lib/python3.8/site-packages/django/core/handlers/base.py", line 220, in _get_response
    response = response.render()
  File "/Users/eduardivanov/Yandex.Disk.localized/Documents/python/workspace/pythonProject/venv/lib/python3.8/site-packages/django/template/response.py", line 114, in render
    self.content = self.rendered_content
  File "/Users/eduardivanov/Yandex.Disk.localized/Documents/python/workspace/pythonProject/venv/lib/python3.8/site-packages/django/template/response.py", line 90, in rendered_content
    template = self.resolve_template(self.template_name)
  File "/Users/eduardivanov/Yandex.Disk.localized/Documents/python/workspace/pythonProject/venv/lib/python3.8/site-packages/django/template/response.py", line 72, in resolve_template
    return select_template(template, using=self.using)
  File "/Users/eduardivanov/Yandex.Disk.localized/Documents/python/workspace/pythonProject/venv/lib/python3.8/site-packages/django/template/loader.py", line 47, in select_template
    raise TemplateDoesNotExist(", ".join(template_name_list), chain=chain)
django.template.exceptions.TemplateDoesNotExist: post_1/post.html
2022-05-14 08:50:37,157 ERROR "GET /news/14 HTTP/1.1" 500 81592 /Users/eduardivanov/Yandex.Disk.localized/Documents/python/workspace/pythonProject/venv/lib/python3.8/site-packages/django/core/servers/basehttp.py None
2022-05-14 08:59:21,744 ERROR Internal Server Error: /upgrade/premium/ /Users/eduardivanov/Yandex.Disk.localized/Documents/python/workspace/pythonProject/venv/lib/python3.8/site-packages/django/utils/log.py (<class 'django.contrib.auth.models.Group.DoesNotExist'>, DoesNotExist('Group matching query does not exist.'), <traceback object at 0x103566fc0>)
Traceback (most recent call last):
  File "/Users/eduardivanov/Yandex.Disk.localized/Documents/python/workspace/pythonProject/venv/lib/python3.8/site-packages/django/core/handlers/exception.py", line 55, in inner
    response = get_response(request)
  File "/Users/eduardivanov/Yandex.Disk.localized/Documents/python/workspace/pythonProject/venv/lib/python3.8/site-packages/django/core/handlers/base.py", line 197, in _get_response
    response = wrapped_callback(request, *callback_args, **callback_kwargs)
  File "/Users/eduardivanov/Yandex.Disk.localized/Documents/python/workspace/pythonProject/venv/lib/python3.8/site-packages/django/contrib/auth/decorators.py", line 23, in _wrapped_view
    return view_func(request, *args, **kwargs)
  File "/Users/eduardivanov/Yandex.Disk.localized/Documents/python/workspace/pythonProject/NewsPaper/NewsPaper/views.py", line 46, in upgrade_premium
    premium_group = Group.objects.get(name='premium')
  File "/Users/eduardivanov/Yandex.Disk.localized/Documents/python/workspace/pythonProject/venv/lib/python3.8/site-packages/django/db/models/manager.py", line 85, in manager_method
    return getattr(self.get_queryset(), name)(*args, **kwargs)
  File "/Users/eduardivanov/Yandex.Disk.localized/Documents/python/workspace/pythonProject/venv/lib/python3.8/site-packages/django/db/models/query.py", line 496, in get
    raise self.model.DoesNotExist(
django.contrib.auth.models.Group.DoesNotExist: Group matching query does not exist.
2022-05-14 08:59:21,750 ERROR "GET /upgrade/premium/ HTTP/1.1" 500 80370 /Users/eduardivanov/Yandex.Disk.localized/Documents/python/workspace/pythonProject/venv/lib/python3.8/site-packages/django/core/servers/basehttp.py None
2022-05-30 19:09:51,359 ERROR Internal Server Error: / /Users/eduardivanov/Yandex.Disk.localized/Documents/python/workspace/pythonProject/venv/lib/python3.8/site-packages/django/utils/log.py (<class 'django.urls.exceptions.NoReverseMatch'>, NoReverseMatch("Reverse for 'set_language' not found. 'set_language' is not a valid view function or pattern name."), <traceback object at 0x103802ac0>)
Traceback (most recent call last):
  File "/Users/eduardivanov/Yandex.Disk.localized/Documents/python/workspace/pythonProject/venv/lib/python3.8/site-packages/django/core/handlers/exception.py", line 55, in inner
    response = get_response(request)
  File "/Users/eduardivanov/Yandex.Disk.localized/Documents/python/workspace/pythonProject/venv/lib/python3.8/site-packages/django/core/handlers/base.py", line 220, in _get_response
    response = response.render()
  File "/Users/eduardivanov/Yandex.Disk.localized/Documents/python/workspace/pythonProject/venv/lib/python3.8/site-packages/django/template/response.py", line 114, in render
    self.content = self.rendered_content
  File "/Users/eduardivanov/Yandex.Disk.localized/Documents/python/workspace/pythonProject/venv/lib/python3.8/site-packages/django/template/response.py", line 92, in rendered_content
    return template.render(context, self._request)
  File "/Users/eduardivanov/Yandex.Disk.localized/Documents/python/workspace/pythonProject/venv/lib/python3.8/site-packages/django/template/backends/django.py", line 62, in render
    return self.template.render(context)
  File "/Users/eduardivanov/Yandex.Disk.localized/Documents/python/workspace/pythonProject/venv/lib/python3.8/site-packages/django/template/base.py", line 175, in render
    return self._render(context)
  File "/Users/eduardivanov/Yandex.Disk.localized/Documents/python/workspace/pythonProject/venv/lib/python3.8/site-packages/django/template/base.py", line 167, in _render
    return self.nodelist.render(context)
  File "/Users/eduardivanov/Yandex.Disk.localized/Documents/python/workspace/pythonProject/venv/lib/python3.8/site-packages/django/template/base.py", line 1000, in render
    return SafeString("".join([node.render_annotated(context) for node in self]))
  File "/Users/eduardivanov/Yandex.Disk.localized/Documents/python/workspace/pythonProject/venv/lib/python3.8/site-packages/django/template/base.py", line 1000, in <listcomp>
    return SafeString("".join([node.render_annotated(context) for node in self]))
  File "/Users/eduardivanov/Yandex.Disk.localized/Documents/python/workspace/pythonProject/venv/lib/python3.8/site-packages/django/template/base.py", line 958, in render_annotated
    return self.render(context)
  File "/Users/eduardivanov/Yandex.Disk.localized/Documents/python/workspace/pythonProject/venv/lib/python3.8/site-packages/django/template/loader_tags.py", line 157, in render
    return compiled_parent._render(context)
  File "/Users/eduardivanov/Yandex.Disk.localized/Documents/python/workspace/pythonProject/venv/lib/python3.8/site-packages/django/template/base.py", line 167, in _render
    return self.nodelist.render(context)
  File "/Users/eduardivanov/Yandex.Disk.localized/Documents/python/workspace/pythonProject/venv/lib/python3.8/site-packages/django/template/base.py", line 1000, in render
    return SafeString("".join([node.render_annotated(context) for node in self]))
  File "/Users/eduardivanov/Yandex.Disk.localized/Documents/python/workspace/pythonProject/venv/lib/python3.8/site-packages/django/template/base.py", line 1000, in <listcomp>
    return SafeString("".join([node.render_annotated(context) for node in self]))
  File "/Users/eduardivanov/Yandex.Disk.localized/Documents/python/workspace/pythonProject/venv/lib/python3.8/site-packages/django/template/base.py", line 958, in render_annotated
    return self.render(context)
  File "/Users/eduardivanov/Yandex.Disk.localized/Documents/python/workspace/pythonProject/venv/lib/python3.8/site-packages/django/template/loader_tags.py", line 63, in render
    result = block.nodelist.render(context)
  File "/Users/eduardivanov/Yandex.Disk.localized/Documents/python/workspace/pythonProject/venv/lib/python3.8/site-packages/django/template/base.py", line 1000, in render
    return SafeString("".join([node.render_annotated(context) for node in self]))
  File "/Users/eduardivanov/Yandex.Disk.localized/Documents/python/workspace/pythonProject/venv/lib/python3.8/site-packages/django/template/base.py", line 1000, in <listcomp>
    return SafeString("".join([node.render_annotated(context) for node in self]))
  File "/Users/eduardivanov/Yandex.Disk.localized/Documents/python/workspace/pythonProject/venv/lib/python3.8/site-packages/django/template/base.py", line 958, in render_annotated
    return self.render(context)
  File "/Users/eduardivanov/Yandex.Disk.localized/Documents/python/workspace/pythonProject/venv/lib/python3.8/site-packages/django/template/defaulttags.py", line 472, in render
    url = reverse(view_name, args=args, kwargs=kwargs, current_app=current_app)
  File "/Users/eduardivanov/Yandex.Disk.localized/Documents/python/workspace/pythonProject/venv/lib/python3.8/site-packages/django/urls/base.py", line 88, in reverse
    return resolver._reverse_with_prefix(view, prefix, *args, **kwargs)
  File "/Users/eduardivanov/Yandex.Disk.localized/Documents/python/workspace/pythonProject/venv/lib/python3.8/site-packages/django/urls/resolvers.py", line 802, in _reverse_with_prefix
    raise NoReverseMatch(msg)
django.urls.exceptions.NoReverseMatch: Reverse for 'set_language' not found. 'set_language' is not a valid view function or pattern name.
2022-05-30 19:09:51,365 ERROR "GET / HTTP/1.1" 500 166328 /Users/eduardivanov/Yandex.Disk.localized/Documents/python/workspace/pythonProject/venv/lib/python3.8/site-packages/django/core/servers/basehttp.py None
2022-05-31 17:38:47,122 ERROR Internal Server Error: /admin/news/category/ /Users/eduardivanov/Yandex.Disk.localized/Documents/python/workspace/pythonProject/venv/lib/python3.8/site-packages/django/utils/log.py (<class 'django.db.utils.OperationalError'>, OperationalError('no such column: news_category.name_en'), <traceback object at 0x107771780>)
Traceback (most recent call last):
  File "/Users/eduardivanov/Yandex.Disk.localized/Documents/python/workspace/pythonProject/venv/lib/python3.8/site-packages/django/db/backends/utils.py", line 89, in _execute
    return self.cursor.execute(sql, params)
  File "/Users/eduardivanov/Yandex.Disk.localized/Documents/python/workspace/pythonProject/venv/lib/python3.8/site-packages/django/db/backends/sqlite3/base.py", line 477, in execute
    return Database.Cursor.execute(self, query, params)
sqlite3.OperationalError: no such column: news_category.name_en

The above exception was the direct cause of the following exception:

Traceback (most recent call last):
  File "/Users/eduardivanov/Yandex.Disk.localized/Documents/python/workspace/pythonProject/venv/lib/python3.8/site-packages/django/core/handlers/exception.py", line 55, in inner
    response = get_response(request)
  File "/Users/eduardivanov/Yandex.Disk.localized/Documents/python/workspace/pythonProject/venv/lib/python3.8/site-packages/django/core/handlers/base.py", line 197, in _get_response
    response = wrapped_callback(request, *callback_args, **callback_kwargs)
  File "/Users/eduardivanov/Yandex.Disk.localized/Documents/python/workspace/pythonProject/venv/lib/python3.8/site-packages/django/contrib/admin/options.py", line 683, in wrapper
    return self.admin_site.admin_view(view)(*args, **kwargs)
  File "/Users/eduardivanov/Yandex.Disk.localized/Documents/python/workspace/pythonProject/venv/lib/python3.8/site-packages/django/utils/decorators.py", line 133, in _wrapped_view
    response = view_func(request, *args, **kwargs)
  File "/Users/eduardivanov/Yandex.Disk.localized/Documents/python/workspace/pythonProject/venv/lib/python3.8/site-packages/django/views/decorators/cache.py", line 62, in _wrapped_view_func
    response = view_func(request, *args, **kwargs)
  File "/Users/eduardivanov/Yandex.Disk.localized/Documents/python/workspace/pythonProject/venv/lib/python3.8/site-packages/django/contrib/admin/sites.py", line 242, in inner
    return view(request, *args, **kwargs)
  File "/Users/eduardivanov/Yandex.Disk.localized/Documents/python/workspace/pythonProject/venv/lib/python3.8/site-packages/django/utils/decorators.py", line 46, in _wrapper
    return bound_method(*args, **kwargs)
  File "/Users/eduardivanov/Yandex.Disk.localized/Documents/python/workspace/pythonProject/venv/lib/python3.8/site-packages/django/utils/decorators.py", line 133, in _wrapped_view
    response = view_func(request, *args, **kwargs)
  File "/Users/eduardivanov/Yandex.Disk.localized/Documents/python/workspace/pythonProject/venv/lib/python3.8/site-packages/django/contrib/admin/options.py", line 2063, in changelist_view
    "selection_note": _("0 of %(cnt)s selected") % {"cnt": len(cl.result_list)},
  File "/Users/eduardivanov/Yandex.Disk.localized/Documents/python/workspace/pythonProject/venv/lib/python3.8/site-packages/django/db/models/query.py", line 302, in __len__
    self._fetch_all()
  File "/Users/eduardivanov/Yandex.Disk.localized/Documents/python/workspace/pythonProject/venv/lib/python3.8/site-packages/django/db/models/query.py", line 1507, in _fetch_all
    self._result_cache = list(self._iterable_class(self))
  File "/Users/eduardivanov/Yandex.Disk.localized/Documents/python/workspace/pythonProject/venv/lib/python3.8/site-packages/django/db/models/query.py", line 57, in __iter__
    results = compiler.execute_sql(
  File "/Users/eduardivanov/Yandex.Disk.localized/Documents/python/workspace/pythonProject/venv/lib/python3.8/site-packages/django/db/models/sql/compiler.py", line 1361, in execute_sql
    cursor.execute(sql, params)
  File "/Users/eduardivanov/Yandex.Disk.localized/Documents/python/workspace/pythonProject/venv/lib/python3.8/site-packages/django/db/backends/utils.py", line 103, in execute
    return super().execute(sql, params)
  File "/Users/eduardivanov/Yandex.Disk.localized/Documents/python/workspace/pythonProject/venv/lib/python3.8/site-packages/django/db/backends/utils.py", line 67, in execute
    return self._execute_with_wrappers(
  File "/Users/eduardivanov/Yandex.Disk.localized/Documents/python/workspace/pythonProject/venv/lib/python3.8/site-packages/django/db/backends/utils.py", line 80, in _execute_with_wrappers
    return executor(sql, params, many, context)
  File "/Users/eduardivanov/Yandex.Disk.localized/Documents/python/workspace/pythonProject/venv/lib/python3.8/site-packages/django/db/backends/utils.py", line 89, in _execute
    return self.cursor.execute(sql, params)
  File "/Users/eduardivanov/Yandex.Disk.localized/Documents/python/workspace/pythonProject/venv/lib/python3.8/site-packages/django/db/utils.py", line 91, in __exit__
    raise dj_exc_value.with_traceback(traceback) from exc_value
  File "/Users/eduardivanov/Yandex.Disk.localized/Documents/python/workspace/pythonProject/venv/lib/python3.8/site-packages/django/db/backends/utils.py", line 89, in _execute
    return self.cursor.execute(sql, params)
  File "/Users/eduardivanov/Yandex.Disk.localized/Documents/python/workspace/pythonProject/venv/lib/python3.8/site-packages/django/db/backends/sqlite3/base.py", line 477, in execute
    return Database.Cursor.execute(self, query, params)
django.db.utils.OperationalError: no such column: news_category.name_en
2022-05-31 17:38:47,131 ERROR "GET /admin/news/category/ HTTP/1.1" 500 152036 /Users/eduardivanov/Yandex.Disk.localized/Documents/python/workspace/pythonProject/venv/lib/python3.8/site-packages/django/core/servers/basehttp.py None
2022-05-31 17:39:10,086 ERROR Internal Server Error: /admin/news/comment/ /Users/eduardivanov/Yandex.Disk.localized/Documents/python/workspace/pythonProject/venv/lib/python3.8/site-packages/django/utils/log.py (<class 'django.db.utils.OperationalError'>, OperationalError('no such column: news_comment.text_en'), <traceback object at 0x1077a3f40>)
Traceback (most recent call last):
  File "/Users/eduardivanov/Yandex.Disk.localized/Documents/python/workspace/pythonProject/venv/lib/python3.8/site-packages/django/db/backends/utils.py", line 89, in _execute
    return self.cursor.execute(sql, params)
  File "/Users/eduardivanov/Yandex.Disk.localized/Documents/python/workspace/pythonProject/venv/lib/python3.8/site-packages/django/db/backends/sqlite3/base.py", line 477, in execute
    return Database.Cursor.execute(self, query, params)
sqlite3.OperationalError: no such column: news_comment.text_en

The above exception was the direct cause of the following exception:

Traceback (most recent call last):
  File "/Users/eduardivanov/Yandex.Disk.localized/Documents/python/workspace/pythonProject/venv/lib/python3.8/site-packages/django/core/handlers/exception.py", line 55, in inner
    response = get_response(request)
  File "/Users/eduardivanov/Yandex.Disk.localized/Documents/python/workspace/pythonProject/venv/lib/python3.8/site-packages/django/core/handlers/base.py", line 197, in _get_response
    response = wrapped_callback(request, *callback_args, **callback_kwargs)
  File "/Users/eduardivanov/Yandex.Disk.localized/Documents/python/workspace/pythonProject/venv/lib/python3.8/site-packages/django/contrib/admin/options.py", line 683, in wrapper
    return self.admin_site.admin_view(view)(*args, **kwargs)
  File "/Users/eduardivanov/Yandex.Disk.localized/Documents/python/workspace/pythonProject/venv/lib/python3.8/site-packages/django/utils/decorators.py", line 133, in _wrapped_view
    response = view_func(request, *args, **kwargs)
  File "/Users/eduardivanov/Yandex.Disk.localized/Documents/python/workspace/pythonProject/venv/lib/python3.8/site-packages/django/views/decorators/cache.py", line 62, in _wrapped_view_func
    response = view_func(request, *args, **kwargs)
  File "/Users/eduardivanov/Yandex.Disk.localized/Documents/python/workspace/pythonProject/venv/lib/python3.8/site-packages/django/contrib/admin/sites.py", line 242, in inner
    return view(request, *args, **kwargs)
  File "/Users/eduardivanov/Yandex.Disk.localized/Documents/python/workspace/pythonProject/venv/lib/python3.8/site-packages/django/utils/decorators.py", line 46, in _wrapper
    return bound_method(*args, **kwargs)
  File "/Users/eduardivanov/Yandex.Disk.localized/Documents/python/workspace/pythonProject/venv/lib/python3.8/site-packages/django/utils/decorators.py", line 133, in _wrapped_view
    response = view_func(request, *args, **kwargs)
  File "/Users/eduardivanov/Yandex.Disk.localized/Documents/python/workspace/pythonProject/venv/lib/python3.8/site-packages/django/contrib/admin/options.py", line 2063, in changelist_view
    "selection_note": _("0 of %(cnt)s selected") % {"cnt": len(cl.result_list)},
  File "/Users/eduardivanov/Yandex.Disk.localized/Documents/python/workspace/pythonProject/venv/lib/python3.8/site-packages/django/db/models/query.py", line 302, in __len__
    self._fetch_all()
  File "/Users/eduardivanov/Yandex.Disk.localized/Documents/python/workspace/pythonProject/venv/lib/python3.8/site-packages/django/db/models/query.py", line 1507, in _fetch_all
    self._result_cache = list(self._iterable_class(self))
  File "/Users/eduardivanov/Yandex.Disk.localized/Documents/python/workspace/pythonProject/venv/lib/python3.8/site-packages/django/db/models/query.py", line 57, in __iter__
    results = compiler.execute_sql(
  File "/Users/eduardivanov/Yandex.Disk.localized/Documents/python/workspace/pythonProject/venv/lib/python3.8/site-packages/django/db/models/sql/compiler.py", line 1361, in execute_sql
    cursor.execute(sql, params)
  File "/Users/eduardivanov/Yandex.Disk.localized/Documents/python/workspace/pythonProject/venv/lib/python3.8/site-packages/django/db/backends/utils.py", line 103, in execute
    return super().execute(sql, params)
  File "/Users/eduardivanov/Yandex.Disk.localized/Documents/python/workspace/pythonProject/venv/lib/python3.8/site-packages/django/db/backends/utils.py", line 67, in execute
    return self._execute_with_wrappers(
  File "/Users/eduardivanov/Yandex.Disk.localized/Documents/python/workspace/pythonProject/venv/lib/python3.8/site-packages/django/db/backends/utils.py", line 80, in _execute_with_wrappers
    return executor(sql, params, many, context)
  File "/Users/eduardivanov/Yandex.Disk.localized/Documents/python/workspace/pythonProject/venv/lib/python3.8/site-packages/django/db/backends/utils.py", line 89, in _execute
    return self.cursor.execute(sql, params)
  File "/Users/eduardivanov/Yandex.Disk.localized/Documents/python/workspace/pythonProject/venv/lib/python3.8/site-packages/django/db/utils.py", line 91, in __exit__
    raise dj_exc_value.with_traceback(traceback) from exc_value
  File "/Users/eduardivanov/Yandex.Disk.localized/Documents/python/workspace/pythonProject/venv/lib/python3.8/site-packages/django/db/backends/utils.py", line 89, in _execute
    return self.cursor.execute(sql, params)
  File "/Users/eduardivanov/Yandex.Disk.localized/Documents/python/workspace/pythonProject/venv/lib/python3.8/site-packages/django/db/backends/sqlite3/base.py", line 477, in execute
    return Database.Cursor.execute(self, query, params)
django.db.utils.OperationalError: no such column: news_comment.text_en
2022-05-31 17:39:10,089 ERROR "GET /admin/news/comment/ HTTP/1.1" 500 172145 /Users/eduardivanov/Yandex.Disk.localized/Documents/python/workspace/pythonProject/venv/lib/python3.8/site-packages/django/core/servers/basehttp.py None
2022-05-31 17:39:14,998 ERROR Internal Server Error: /admin/news/postcategory/ /Users/eduardivanov/Yandex.Disk.localized/Documents/python/workspace/pythonProject/venv/lib/python3.8/site-packages/django/utils/log.py (<class 'django.db.utils.OperationalError'>, OperationalError('no such column: news_post.title_en'), <traceback object at 0x107910900>)
Traceback (most recent call last):
  File "/Users/eduardivanov/Yandex.Disk.localized/Documents/python/workspace/pythonProject/venv/lib/python3.8/site-packages/django/db/backends/utils.py", line 89, in _execute
    return self.cursor.execute(sql, params)
  File "/Users/eduardivanov/Yandex.Disk.localized/Documents/python/workspace/pythonProject/venv/lib/python3.8/site-packages/django/db/backends/sqlite3/base.py", line 477, in execute
    return Database.Cursor.execute(self, query, params)
sqlite3.OperationalError: no such column: news_post.title_en

The above exception was the direct cause of the following exception:

Traceback (most recent call last):
  File "/Users/eduardivanov/Yandex.Disk.localized/Documents/python/workspace/pythonProject/venv/lib/python3.8/site-packages/django/core/handlers/exception.py", line 55, in inner
    response = get_response(request)
  File "/Users/eduardivanov/Yandex.Disk.localized/Documents/python/workspace/pythonProject/venv/lib/python3.8/site-packages/django/core/handlers/base.py", line 197, in _get_response
    response = wrapped_callback(request, *callback_args, **callback_kwargs)
  File "/Users/eduardivanov/Yandex.Disk.localized/Documents/python/workspace/pythonProject/venv/lib/python3.8/site-packages/django/contrib/admin/options.py", line 683, in wrapper
    return self.admin_site.admin_view(view)(*args, **kwargs)
  File "/Users/eduardivanov/Yandex.Disk.localized/Documents/python/workspace/pythonProject/venv/lib/python3.8/site-packages/django/utils/decorators.py", line 133, in _wrapped_view
    response = view_func(request, *args, **kwargs)
  File "/Users/eduardivanov/Yandex.Disk.localized/Documents/python/workspace/pythonProject/venv/lib/python3.8/site-packages/django/views/decorators/cache.py", line 62, in _wrapped_view_func
    response = view_func(request, *args, **kwargs)
  File "/Users/eduardivanov/Yandex.Disk.localized/Documents/python/workspace/pythonProject/venv/lib/python3.8/site-packages/django/contrib/admin/sites.py", line 242, in inner
    return view(request, *args, **kwargs)
  File "/Users/eduardivanov/Yandex.Disk.localized/Documents/python/workspace/pythonProject/venv/lib/python3.8/site-packages/django/utils/decorators.py", line 46, in _wrapper
    return bound_method(*args, **kwargs)
  File "/Users/eduardivanov/Yandex.Disk.localized/Documents/python/workspace/pythonProject/venv/lib/python3.8/site-packages/django/utils/decorators.py", line 133, in _wrapped_view
    response = view_func(request, *args, **kwargs)
  File "/Users/eduardivanov/Yandex.Disk.localized/Documents/python/workspace/pythonProject/venv/lib/python3.8/site-packages/django/contrib/admin/options.py", line 2063, in changelist_view
    "selection_note": _("0 of %(cnt)s selected") % {"cnt": len(cl.result_list)},
  File "/Users/eduardivanov/Yandex.Disk.localized/Documents/python/workspace/pythonProject/venv/lib/python3.8/site-packages/django/db/models/query.py", line 302, in __len__
    self._fetch_all()
  File "/Users/eduardivanov/Yandex.Disk.localized/Documents/python/workspace/pythonProject/venv/lib/python3.8/site-packages/django/db/models/query.py", line 1507, in _fetch_all
    self._result_cache = list(self._iterable_class(self))
  File "/Users/eduardivanov/Yandex.Disk.localized/Documents/python/workspace/pythonProject/venv/lib/python3.8/site-packages/django/db/models/query.py", line 57, in __iter__
    results = compiler.execute_sql(
  File "/Users/eduardivanov/Yandex.Disk.localized/Documents/python/workspace/pythonProject/venv/lib/python3.8/site-packages/django/db/models/sql/compiler.py", line 1361, in execute_sql
    cursor.execute(sql, params)
  File "/Users/eduardivanov/Yandex.Disk.localized/Documents/python/workspace/pythonProject/venv/lib/python3.8/site-packages/django/db/backends/utils.py", line 103, in execute
    return super().execute(sql, params)
  File "/Users/eduardivanov/Yandex.Disk.localized/Documents/python/workspace/pythonProject/venv/lib/python3.8/site-packages/django/db/backends/utils.py", line 67, in execute
    return self._execute_with_wrappers(
  File "/Users/eduardivanov/Yandex.Disk.localized/Documents/python/workspace/pythonProject/venv/lib/python3.8/site-packages/django/db/backends/utils.py", line 80, in _execute_with_wrappers
    return executor(sql, params, many, context)
  File "/Users/eduardivanov/Yandex.Disk.localized/Documents/python/workspace/pythonProject/venv/lib/python3.8/site-packages/django/db/backends/utils.py", line 89, in _execute
    return self.cursor.execute(sql, params)
  File "/Users/eduardivanov/Yandex.Disk.localized/Documents/python/workspace/pythonProject/venv/lib/python3.8/site-packages/django/db/utils.py", line 91, in __exit__
    raise dj_exc_value.with_traceback(traceback) from exc_value
  File "/Users/eduardivanov/Yandex.Disk.localized/Documents/python/workspace/pythonProject/venv/lib/python3.8/site-packages/django/db/backends/utils.py", line 89, in _execute
    return self.cursor.execute(sql, params)
  File "/Users/eduardivanov/Yandex.Disk.localized/Documents/python/workspace/pythonProject/venv/lib/python3.8/site-packages/django/db/backends/sqlite3/base.py", line 477, in execute
    return Database.Cursor.execute(self, query, params)
django.db.utils.OperationalError: no such column: news_post.title_en
2022-05-31 17:39:15,001 ERROR "GET /admin/news/postcategory/ HTTP/1.1" 500 169830 /Users/eduardivanov/Yandex.Disk.localized/Documents/python/workspace/pythonProject/venv/lib/python3.8/site-packages/django/core/servers/basehttp.py None
